[2025-05-05T06:17:30.258+0000] {taskinstance.py:1956} INFO - Dependencies all met for dep_context=non-requeueable deps ti=<TaskInstance: velib_fetch_data.fetch_velib_data scheduled__2025-05-04T22:15:00+00:00 [queued]>
[2025-05-05T06:17:30.267+0000] {taskinstance.py:1956} INFO - Dependencies all met for dep_context=requeueable deps ti=<TaskInstance: velib_fetch_data.fetch_velib_data scheduled__2025-05-04T22:15:00+00:00 [queued]>
[2025-05-05T06:17:30.268+0000] {taskinstance.py:2170} INFO - Starting attempt 1 of 2
[2025-05-05T06:17:30.284+0000] {taskinstance.py:2191} INFO - Executing <Task(BashOperator): fetch_velib_data> on 2025-05-04 22:15:00+00:00
[2025-05-05T06:17:30.290+0000] {standard_task_runner.py:60} INFO - Started process 1141 to run task
[2025-05-05T06:17:30.293+0000] {standard_task_runner.py:87} INFO - Running: ['***', 'tasks', 'run', 'velib_fetch_data', 'fetch_velib_data', 'scheduled__2025-05-04T22:15:00+00:00', '--job-id', '36', '--raw', '--subdir', 'DAGS_FOLDER/velib_fetch_dag.py', '--cfg-path', '/tmp/tmpcunwial2']
[2025-05-05T06:17:30.295+0000] {standard_task_runner.py:88} INFO - Job 36: Subtask fetch_velib_data
[2025-05-05T06:17:30.998+0000] {task_command.py:423} INFO - Running <TaskInstance: velib_fetch_data.fetch_velib_data scheduled__2025-05-04T22:15:00+00:00 [running]> on host ebcb33ff74c6
[2025-05-05T06:17:31.430+0000] {taskinstance.py:2480} INFO - Exporting env vars: AIRFLOW_CTX_DAG_OWNER='***' AIRFLOW_CTX_DAG_ID='velib_fetch_data' AIRFLOW_CTX_TASK_ID='fetch_velib_data' AIRFLOW_CTX_EXECUTION_DATE='2025-05-04T22:15:00+00:00' AIRFLOW_CTX_TRY_NUMBER='1' AIRFLOW_CTX_DAG_RUN_ID='scheduled__2025-05-04T22:15:00+00:00'
[2025-05-05T06:17:31.431+0000] {subprocess.py:63} INFO - Tmp dir root location: /tmp
[2025-05-05T06:17:31.433+0000] {subprocess.py:75} INFO - Running command: ['/usr/bin/bash', '-c', 'python /opt/***/dags/scripts/fetch_data.py']
[2025-05-05T06:17:31.441+0000] {subprocess.py:86} INFO - Output:
[2025-05-05T06:17:31.471+0000] {subprocess.py:93} INFO - Traceback (most recent call last):
[2025-05-05T06:17:31.471+0000] {subprocess.py:93} INFO -   File "/opt/***/dags/scripts/fetch_data.py", line 3, in <module>
[2025-05-05T06:17:31.472+0000] {subprocess.py:93} INFO -     from matplotlib.pylab import f
[2025-05-05T06:17:31.473+0000] {subprocess.py:93} INFO - ModuleNotFoundError: No module named 'matplotlib'
[2025-05-05T06:17:31.475+0000] {subprocess.py:97} INFO - Command exited with return code 1
[2025-05-05T06:17:31.523+0000] {taskinstance.py:2698} ERROR - Task failed with exception
Traceback (most recent call last):
  File "/home/airflow/.local/lib/python3.10/site-packages/airflow/models/taskinstance.py", line 433, in _execute_task
    result = execute_callable(context=context, **execute_callable_kwargs)
  File "/home/airflow/.local/lib/python3.10/site-packages/airflow/operators/bash.py", line 212, in execute
    raise AirflowException(
airflow.exceptions.AirflowException: Bash command failed. The command returned a non-zero exit code 1.
[2025-05-05T06:17:31.526+0000] {taskinstance.py:1138} INFO - Marking task as UP_FOR_RETRY. dag_id=velib_fetch_data, task_id=fetch_velib_data, execution_date=20250504T221500, start_date=20250505T061730, end_date=20250505T061731
[2025-05-05T06:17:31.539+0000] {standard_task_runner.py:107} ERROR - Failed to execute job 36 for task fetch_velib_data (Bash command failed. The command returned a non-zero exit code 1.; 1141)
[2025-05-05T06:17:31.552+0000] {local_task_job_runner.py:234} INFO - Task exited with return code 1
[2025-05-05T06:17:31.608+0000] {taskinstance.py:3280} INFO - 0 downstream tasks scheduled from follow-on schedule check
