[2025-05-05T09:47:32.464+0000] {taskinstance.py:1956} INFO - Dependencies all met for dep_context=non-requeueable deps ti=<TaskInstance: velib_fetch_data.fetch_velib_data manual__2025-05-05T09:38:07.629006+00:00 [queued]>
[2025-05-05T09:47:32.478+0000] {taskinstance.py:1956} INFO - Dependencies all met for dep_context=requeueable deps ti=<TaskInstance: velib_fetch_data.fetch_velib_data manual__2025-05-05T09:38:07.629006+00:00 [queued]>
[2025-05-05T09:47:32.479+0000] {taskinstance.py:2170} INFO - Starting attempt 2 of 2
[2025-05-05T09:47:32.499+0000] {taskinstance.py:2191} INFO - Executing <Task(BashOperator): fetch_velib_data> on 2025-05-05 09:38:07.629006+00:00
[2025-05-05T09:47:32.504+0000] {standard_task_runner.py:60} INFO - Started process 179 to run task
[2025-05-05T09:47:32.509+0000] {standard_task_runner.py:87} INFO - Running: ['***', 'tasks', 'run', 'velib_fetch_data', 'fetch_velib_data', 'manual__2025-05-05T09:38:07.629006+00:00', '--job-id', '68', '--raw', '--subdir', 'DAGS_FOLDER/velib_fetch_dag.py', '--cfg-path', '/tmp/tmp42y7hjou']
[2025-05-05T09:47:32.515+0000] {standard_task_runner.py:88} INFO - Job 68: Subtask fetch_velib_data
[2025-05-05T09:47:33.115+0000] {task_command.py:423} INFO - Running <TaskInstance: velib_fetch_data.fetch_velib_data manual__2025-05-05T09:38:07.629006+00:00 [running]> on host 6e22c01489ce
[2025-05-05T09:47:34.017+0000] {taskinstance.py:2480} INFO - Exporting env vars: AIRFLOW_CTX_DAG_OWNER='***' AIRFLOW_CTX_DAG_ID='velib_fetch_data' AIRFLOW_CTX_TASK_ID='fetch_velib_data' AIRFLOW_CTX_EXECUTION_DATE='2025-05-05T09:38:07.629006+00:00' AIRFLOW_CTX_TRY_NUMBER='2' AIRFLOW_CTX_DAG_RUN_ID='manual__2025-05-05T09:38:07.629006+00:00'
[2025-05-05T09:47:34.019+0000] {subprocess.py:63} INFO - Tmp dir root location: /tmp
[2025-05-05T09:47:34.021+0000] {subprocess.py:75} INFO - Running command: ['/usr/bin/bash', '-c', 'python /opt/***/dags/scripts/fetch_data.py']
[2025-05-05T09:47:34.029+0000] {subprocess.py:86} INFO - Output:
[2025-05-05T09:47:34.080+0000] {subprocess.py:93} INFO - Traceback (most recent call last):
[2025-05-05T09:47:34.080+0000] {subprocess.py:93} INFO -   File "/opt/***/dags/scripts/fetch_data.py", line 3, in <module>
[2025-05-05T09:47:34.085+0000] {subprocess.py:93} INFO -     from matplotlib.pylab import f
[2025-05-05T09:47:34.086+0000] {subprocess.py:93} INFO - ModuleNotFoundError: No module named 'matplotlib'
[2025-05-05T09:47:34.089+0000] {subprocess.py:97} INFO - Command exited with return code 1
[2025-05-05T09:47:34.234+0000] {taskinstance.py:2698} ERROR - Task failed with exception
Traceback (most recent call last):
  File "/home/airflow/.local/lib/python3.10/site-packages/airflow/models/taskinstance.py", line 433, in _execute_task
    result = execute_callable(context=context, **execute_callable_kwargs)
  File "/home/airflow/.local/lib/python3.10/site-packages/airflow/operators/bash.py", line 212, in execute
    raise AirflowException(
airflow.exceptions.AirflowException: Bash command failed. The command returned a non-zero exit code 1.
[2025-05-05T09:47:34.239+0000] {taskinstance.py:1138} INFO - Marking task as FAILED. dag_id=velib_fetch_data, task_id=fetch_velib_data, execution_date=20250505T093807, start_date=20250505T094732, end_date=20250505T094734
[2025-05-05T09:47:34.271+0000] {standard_task_runner.py:107} ERROR - Failed to execute job 68 for task fetch_velib_data (Bash command failed. The command returned a non-zero exit code 1.; 179)
[2025-05-05T09:47:34.291+0000] {local_task_job_runner.py:234} INFO - Task exited with return code 1
[2025-05-05T09:47:34.454+0000] {taskinstance.py:3280} INFO - 0 downstream tasks scheduled from follow-on schedule check
